<model name="robot_{% ROBOT_NUM %}" canonical_link="chassis">
	<pose relative_to="world">{% POSE %}</pose>
	<link name="chassis">
		<pose relative_to="__model__">0.5 0 0.4 0 0 0</pose>
		<inertial>
			<!--inertial properties of the link mass, inertia matix-->
			<mass>{% BODY_MASS %}</mass>
			<inertia>
				<ixx>0.095329</ixx>
				<ixy>0</ixy>
				<ixz>0</ixz>
				<iyy>0.381317</iyy>
				<iyz>0</iyz>
				<izz>0.476646</izz>
			</inertia>
		</inertial>
		<visual name='visual'>
			<geometry>
				<box>
					<size>{% LENGTH %} {% WIDTH %} {% HEIGHT %}</size>
				</box>
			</geometry>
			<material>
				<ambient>0.0 0.0 1.0 1</ambient>
				<diffuse>0.0 0.0 1.0 1</diffuse>
				<specular>0.0 0.0 1.0 1</specular>
			</material>
		</visual>
		<collision name='collision'>
			<geometry>
				<box>
					<size>{% LENGTH %} {% WIDTH %} {% HEIGHT %}</size>
				</box>
			</geometry>
      <surface>
        <friction>
          <ode>
            <mu>0.001</mu>
            <mu2>0.001</mu2>
          </ode>
        </friction>
      </surface>
		</collision>
	</link>
	<link name='right_wheel'>
		<pose relative_to="chassis">0 -{% WHEEL_Y_OFFSET %} {% WHEEL_Z_OFFSET %} -1.5707 0 0</pose>
		<!--angles are in radian-->
		<inertial>
			<mass>{% WHEEL_MASS %}</mass>
			<inertia>
				<ixx>0.043333</ixx>
				<ixy>0</ixy>
				<ixz>0</ixz>
				<iyy>0.043333</iyy>
				<iyz>0</iyz>
				<izz>0.08</izz>
			</inertia>
		</inertial>
		<visual name='visual'>
			<geometry>
				<cylinder>
					<radius>{% WHEEL_RAD %}</radius>
					<length>{% WHEEL_DEPTH %}</length>
				</cylinder>
			</geometry>
			<material>
				<ambient>1.0 0.0 0.0 1</ambient>
				<diffuse>1.0 0.0 0.0 1</diffuse>
				<specular>1.0 0.0 0.0 1</specular>
			</material>
		</visual>
		<collision name='collision'>
			<geometry>
				<cylinder>
					<radius>{% WHEEL_RAD %}</radius>
					<length>{% WHEEL_DEPTH %}</length>
				</cylinder>
			</geometry>
		</collision>
	</link>
	<link name='left_wheel'>
		<pose relative_to="chassis">0 {% WHEEL_Y_OFFSET %} {% WHEEL_Z_OFFSET %} -1.5707 0 0</pose>
		<!--angles are in radian-->
		<inertial>
			<mass>{% WHEEL_MASS %}</mass>
			<inertia>
				<ixx>0.043333</ixx>
				<ixy>0</ixy>
				<ixz>0</ixz>
				<iyy>0.043333</iyy>
				<iyz>0</iyz>
				<izz>0.08</izz>
			</inertia>
		</inertial>
		<visual name='visual'>
			<geometry>
				<cylinder>
					<radius>{% WHEEL_RAD %}</radius>
					<length>{% WHEEL_DEPTH %}</length>
				</cylinder>
			</geometry>
			<material>
				<ambient>1.0 0.0 0.0 1</ambient>
				<diffuse>1.0 0.0 0.0 1</diffuse>
				<specular>1.0 0.0 0.0 1</specular>
			</material>
		</visual>
		<collision name='collision'>
			<geometry>
				<cylinder>
					<radius>{% WHEEL_RAD %}</radius>
					<length>{% WHEEL_DEPTH %}</length>
				</cylinder>
			</geometry>
		</collision>
	</link>
	<joint name='left_wheel_joint' type='revolute'>
		<pose relative_to='left_wheel'/>
		<parent>chassis</parent>
		<child>left_wheel</child>
		<axis>
			<xyz expressed_in='__model__'>0 1 0</xyz>
			<!--can be defined as any frame or even arbitrary frames-->
			<limit>
				<lower>-1.79769e+308</lower>
				<!--negative infinity-->
				<upper>1.79769e+308</upper>
				<!--positive infinity-->
			</limit>
		</axis>
	</joint>
	<joint name='right_wheel_joint' type='revolute'>
		<pose relative_to='right_wheel'/>
		<parent>chassis</parent>
		<child>right_wheel</child>
		<axis>
			<xyz expressed_in='__model__'>0 1 0</xyz>
			<limit>
				<lower>-1.79769e+308</lower>
				<!--negative infinity-->
				<upper>1.79769e+308</upper>
				<!--positive infinity-->
			</limit>
		</axis>
	</joint>
  <plugin
    filename="gz-sim-diff-drive-system"
    name="gz::sim::systems::DiffDrive">
    <left_joint>left_wheel_joint</left_joint>
    <right_joint>right_wheel_joint</right_joint>
    <wheel_separation>{% WHEEL_SEPARATION %}</wheel_separation>
    <wheel_radius>{% WHEEL_RAD %}</wheel_radius>
    <odom_publish_frequency>1</odom_publish_frequency>
  </plugin>
</model>

